Workbook
Name _: #REF!
Name _______kjnjknv: #REF!
Name _______kjnjknv: #REF!
Name _______kjnjknv: #REF!
Name _______kjnjknv: #REF!
Name _______kjnjknv: #REF!
Name _______kjnjknv: #REF!
Name _______kjnjknv: #REF!
Name _______kjnjknv: #REF!
Name _______kjnjknv: #REF!
Name _______kjnjknv: #REF!
Name _______kjnjknv: #REF!
Name _______kjnjknv: #REF!
Name _______kjnjknv: #REF!
Name _______kjnjknv: #REF!
Name _______kjnjknv: #REF!
Name _______kjnjknv: #REF!
Name ___ms4: '[1]Legend 2'!$B$16:$B$35
Name ___ms4: '[1]Legend 2'!$B$16:$B$35
Name ___ms4: #REF!
Name __ms4: '[1]Legend 2'!$B$16:$B$35
Name __ms4: '[1]Legend 2'!$B$16:$B$35
Name __ms4: #REF!
Name _jkk: #REF!
Name _ms4: '[1]Legend 2'!$B$16:$B$35
Name _ms4: '[1]Legend 2'!$B$16:$B$35
Name _ms4: #REF!
Name _ReplyAwaited: #REF!
Name _ReplyAwaited: #REF!
Name _ReplyAwaited: #REF!
Name _ReplyAwaited: #REF!
Name _ReplyAwaited: #REF!
Name _ReplyAwaited: #REF!
Name _ReplyAwaited: #REF!
Name _ReplyAwaited: #REF!
Name _ReplyAwaited: #REF!
Name _ReplyAwaited: #REF!
Name _ReplyAwaited: #REF!
Name _ReplyAwaited: #REF!
Name _ReplyAwaited: #REF!
Name aa: #REF!
Name aa: #REF!
Name aa: #REF!
Name aa: #REF!
Name aa: #REF!
Name aa: #REF!
Name aa: #REF!
Name aa: #REF!
Name aa: #REF!
Name aa: #REF!
Name aa: #REF!
Name aa: #REF!
Name aa: #REF!
Name aa: #REF!
Name aa: #REF!
Name aa: #REF!
Name aa: #REF!
Name aa: #REF!
Name aa: #REF!
Name aa: #REF!

Sheet Title Page

Sheet Content
C10: Table of Contents – RTD Ice Tea – France, Netherlands and Portugal
A33: Copyright © 2025 WNS (Holdings) Ltd. All rights reserved.

Sheet Objective, Scope and Approach
B5: Objective and Scope
B7: To develop a process should cost model for RTD Ice Tea in France, Netherlands and Portugal
B9: Approach
B12: – Carried out secondary research to form an initial understanding of the RTD Ice Tea production and packaging process and obtained information about the key steps involved – Studied documents such as research papers, news articles, company websites, and company information and presentations and viewed videos on YouTube to further understand the process – Undertook extensive secondary research to identify relevant stakeholders such as machinery suppliers, equipment suppliers and industry experts | D12: – Carried out secondary and primary research to understand the associated cost heads – Conducted interviews with industry experts, along with expert to understand key operational procedures followed in a plant, along with product dimensions, packaging quantity, and other specifications – Conducted extensive primary research to source information on the prices of machineries by contacting machinery suppliers – Studied annual report of manufacturers to validate information on the fixed and variable costs associated with RTD Ice Tea and packaging | F12: – Synthesized the findings obtained from secondary and primary research sources to develop the cost model – Extracted relevant insights regarding various cost heads – Highlighted the assumptions and benchmarks that were considered to build the cost model
A14: Copyright © 2025 WNS (Holdings) Ltd. All rights reserved.
B18: Plant Building, Installation, and Other Infrastructure Cost

Sheet Production Process
B5: Production Process – RTD Ice Tea
B126: Note: The production process is based on information available through secondary research sources and has been validated through interviews with industry participants
A128: Copyright © 2025 WNS (Holdings) Ltd. All rights reserved.

Sheet Input Sheet
B5: General information about the CM
B6: Key Parameters | C6: Sub-parameters | D6: Input Cells | E6: Units
B7: Number of Production Lines | D7: 1
B8: Production Info | C8: Number of Shifts/day (France) | D8: 3 | E8: Shifts/day
C9: Number of Shifts/day (Netherlands) | D9: 3 | E9: Shifts/day
C10: Number of Shifts/day (Portugal) | D10: 3 | E10: Shifts/day
C11: Number of Shifts/day (Country B) | D11: 3 | E11: Shifts/day
C12: Working Hours per Shift (France) | D12: 8 | E12: Hours/shift
C13: Working Hours per Shift (Netherlands) | D13: 8 | E13: Hours/shift
C14: Working Hours per Shift (Portugal) | D14: 8 | E14: Hours/shift
C15: Working Hours per Shift (Country B) | D15: 8 | E15: Hours/shift
C16: Total Working Days/year (France) | D16: 330 | E16: Days/year
C17: Total Working Days/year (Netherlands) | D17: 320 | E17: Days/year
C18: Total Working Days/year (Portugal) | D18: 310 | E18: Days/year
C19: Total Working Days/year (Country B) | D19: 330 | E19: Days/year
B20: Plant Details and Capex | C20: Construction Rate – France | D20: 1330 | E20: €/sqm
C21: Construction Rate – Netherlands | D21: 1220 | E21: €/sqm
C22: Construction Rate – Portugal | D22: 1429 | E22: €/sqm
C23: Construction Rate – Country B | D23: 1119 | E23: €/sqm
C24: Industrial Land Rate – France | D24: 80 | E24: €/sqm
C25: Industrial Land Rate – Netherlands | D25: 90 | E25: €/sqm
C26: Industrial Land Rate – Portugal | D26: 65 | E26: €/sqm
C27: Industrial Land Rate – Country B | D27: 18 | E27: €/sqm
C28: Total Plant Area3 | D28: 15000 | E28: sq. m
B29: Utility Costs | C29: Electricity – France | D29: 0.15825473 | E29: €/kWh
C30: Electricity – Netherlands | D30: 0.1578283 | E30: €/kWh
C31: Electricity – Portugal | D31: 0.13 | E31: €/kWh
C32: Electricity – Country B | D32: 0.15 | E32: €/kWh
C33: Natural Gas – France | D33: 0.076756443 | E33: €/kWh
C34: Natural Gas – Netherlands | D34: 0.076756443 | E34: €/kWh
C35: Natural Gas – Portugal | D35: 0.1 | E35: €/kWh
C36: Natural Gas – Country B | D36: 0.07 | E36: €/kWh
C37: Industrial Steam – France | D37: 68.5 | E37: €/MT
C38: Industrial Steam – Netherlands | D38: 68 | E38: €/MT
C39: Industrial Steam – Portugal | D39: 39.5 | E39: €/MT
C40: Industrial Steam – Country B | D40: 68.64 | E40: €/MT
C41: Boiler Feed Water – France | D41: 30 | E41: €/MT
... C52: Other Utilities – Country B | D52: 0.15 | E52: of Total Electricity Cost
B53: Other Costs | C53: Selling, General and Administrative Costs | D53: 0.6 | E53: of total process cost
C54: Other Depreciation Costs | D54: 0.033333333 | E54: of non-machinery cost
...

Sheet Part 1 - Summary

Sheet 1.1 Summary
E2: Bottles | F2: Multipack | G2: Tray | H2: Country | I2: Container Format | J2: Decontamination Process | K2: Product type
E3: 0.25 | F3: 4 | G3: 12 | H3: France | I3: PET Bottle | J3: Dry Aseptic | K3: Carbonated
E4: 0.33 | F4: 6 | G4: 24 | H4: Netherlands | I4: Can | J4: Wet Aseptic | K4: Non-Carbonated
B5: Summary – RTD Ice Tea | E5: 0.5 | F5: 8 | H5: Portugal
E6: 1 | F6: 12 | H6: Country B
B7: Indicates drop-down menu | C7: Indicates input cell | E7: 1.5 | R7: Vietnam
B8: Product Name | C8: RTD Ice Tea | E8: 2
B9: Production Country | C9: Netherlands
B10: Time Period | C10: December
B11: Currency | C11: EUR (€)
B12: RTD Ice Tea Machinery | C12: Fully-Automated | D12: << for machinery type | E12: Please click for definition | G12: Multipack | H12: Can
B13: Facility Type | C13: New | D13: << for facility type | E13: Please click for definition | G13: Tray
B14: Product Type | C14: Non-Carbonated | D14: << for product type
B15: SKU Packing Type | C15: PET Bottle | D15: << for packing type | I15: 4 | J15: 4*6
B16: SKU Size | C16: 2 | D16: << for Unit SKU Size
B17: Number of Units in Multipacks | C17: 6 | D17: << for Secondary Packaging | H17: Dry Aseptic | I17: 8 | J17: 8*3
B18: Tray Combination | C18: =IF(C17=4,"4*6",IF(C17=6,"6*4",IF(C17=8,"8*3",IF(C17=12,"12*2","24*1")))) -> 6*4 | D18: << for multipacks in a tray | H18: Wet Aseptic | I18: 12 | J18: 12*2
B19: PET Bottle Decontamination Process (For Can Packing, Select " – ") | C19: Dry Aseptic | D19: << for PET decontamination type | H19: –
B20: Scale of Production | C20: High-scale
B21: Site Complexity | C21: Low | D21: << for site complexity | E21: Please click for definition
B25: Cost Structure Summary – RTD Ice Tea
G26: =B25 -> Cost Structure Summary – RTD Ice Tea
B27: Parameters | C27: Cost Breakdown* | D27: Cost Breakdown (€/MT) | E27: Cost per Consumer/Unit Column
B28: Total Equipment Cost | C28: =D28/$D$32 -> 0.023571088 | D28: ='1.1 Summary'!D45+'1.1 Summary'!D77 -> 2.5086824 | E28: =D28/(1000/$C$16) -> 0.0050173647
B29: Total Utility Cost | C29: =D29/$D$32 -> 0.20057098 | D29: ='1.1 Summary'!D46+'1.1 Summary'!D78 -> 21.346868 | E29: =D29/(1000/$C$16) -> 0.042693736
B30: Total Labour Cost | C30: =D30/$D$32 -> 0.10901249 | D30: ='1.1 Summary'!D79+'1.1 Summary'!D47 -> 11.602253 | E30: =D30/(1000/$C$16) -> 0.023204505
B31: Total Overhead and Indirect Cost | C31: =D31/$D$32 -> 0.66684544 | D31: =D49+D81 -> 70.972686 | E31: =D31/(1000/$C$16) -> 0.14194537
B32: Total Production Cost | C32: =SUM(C28:C31) -> 1 | D32: =SUM(D28:D31) -> 106.43049 | E32: =D32/(1000/C16) -> 0.21286098
B35: Average Margins Earned by Supplier | C35: High | D35: =IF(C35="High",20%,IF(C35="Medium",15%,10%)) -> 0.2 | E35: Please click for definition
B36: Production Cost including Margin Earned by Supplier | D36: =(D35*D32)+D32 -> 127.71659
B38: Purchase Price (€/MT)
B40: Gap (€/MT) | D40: =IF(D38="","Please enter purchase price in cell D35",D38-D36) -> Please enter purchase price in cell D35
B42: Cost Breakdown – Processes – By Cost Type | G42: Cost Breakdown – Processes – By Processing Step
B44: Parameters | C44: Cost Breakdown* | D44: Cost Breakdown (€/MT) | G44: Parameters | H44: Cost Breakdown* | I44: Cost Breakdown (€/MT)
B45: Equipment Cost | C45: =D45/$D$48 -> 0.074455554 | D45: =IF('1.1 Summary'!C12="Semi-Automated",SUM('2.1 Cost Model Processes'!E12+'2.1 Cost Model Processes'!E30+'2.1 Cost Model Processes'!E48+'2.1 Cost Model Processes'!E67+'2.1 Cost Model Processes'!E86),SUM('2.1 Cost Model Processes'!I12+'2.1 Cost Model Processes'!I30+'2.1 Cost Model Processes'!I48+'2.1 Cost Model Processes'!I67+'2.1 Cost Model Processes'!I86)) -> 2.3012232 | G45: Water Treatment | H45: =I45/$I$50 -> 0.17075297 | I45: =IF(C12="Semi-Automated",'2.1 Cost Model Processes'!E25,'2.1 Cost Model Processes'!I25) -> 5.2775202
B46: Utility Cost | C46: =D46/$D$48 -> 0.6179917 | D46: =IF('1.1 Summary'!C12="Semi-Automated",SUM('2.1 Cost Model Processes'!E17+'2.1 Cost Model Processes'!E35+'2.1 Cost Model Processes'!E53+'2.1 Cost Model Processes'!E72+'2.1 Cost Model Processes'!E91),SUM('2.1 Cost Model Processes'!I17+'2.1 Cost Model Processes'!I35+'2.1 Cost Model Processes'!I53+'2.1 Cost Model Processes'!I72+'2.1 Cost Model Processes'!I91)) -> 19.10048 | G46: Syrup Preparation | H46: =I46/$I$50 -> 0.25464721 | I46: =IF(C12="Semi-Automated",'2.1 Cost Model Processes'!E43,'2.1 Cost Model Processes'!I43) -> 7.870468
B47: Labour Cost | C47: =D47/$D$48 -> 0.30755274 | D47: =IF('1.1 Summary'!C12="Semi-Automated",SUM('2.1 Cost Model Processes'!E24+'2.1 Cost Model Processes'!E42+'2.1 Cost Model Processes'!E60+'2.1 Cost Model Processes'!E79+'2.1 Cost Model Processes'!E98),SUM('2.1 Cost Model Processes'!I24+'2.1 Cost Model Processes'!I42+'2.1 Cost Model Processes'!I60+'2.1 Cost Model Processes'!I79+'2.1 Cost Model Processes'!I98)) -> 9.5056374 | G47: Carbonising | H47: =I47/$I$50 -> 0 | I47: =IF(C12="Semi-Automated",'2.1 Cost Model Processes'!E100,'2.1 Cost Model Processes'!I100) -> 0
B48: Total Production Cost | C48: =SUM(C45:C47) -> 1 | D48: =SUM(D45:D47) -> 30.907341 | G48: Mixing | H48: =I48/$I$50 -> 0.023815631 | I48: =IF(C12="Semi-Automated",'2.1 Cost Model Processes'!E62,'2.1 Cost Model Processes'!I62) -> 0.7360778
B49: Overheads and Indirect Cost for the Process | D49: =IF(C12="Semi-Automated",'2.1 Cost Model Processes'!E115,'2.1 Cost Model Processes'!I115) -> 58.85206 | G49: Pasteurising | H49: =I49/$I$50 -> 0.55078419 | I49: =IF($C$12="Semi-Automated",'2.1 Cost Model Processes'!E81,'2.1 Cost Model Processes'!I81) -> 17.023275
B50: Total Production Cost (including overheads and indirect cost) | D50: =D48+D49 -> 89.7594 | G50: Total Production Cost | H50: =SUM(H45:H49) -> 1 | I50: =SUM(I45:I49) -> 30.907341
...

Sheet 1.2 Scenario Analysis
B5: Summary – RTD Ice Tea | I5: Carbonated | J5: PET Bottle
I6: Non-Carbonated | J6: Can
B7: Indicates drop-down menu | C7: Indicates input cell | G7: Indicates drop-down menu | H7: Indicates input cell | I7: Big Bag | J7: Carton | K7: Bag in Boxes | L7: Indicates drop-down menu | M7: Indicates input cell
I8: 500 | J8: 4 | K8: 0.4
B9: Product Name | C9: RTD Ice Tea1 | G9: Product Name | H9: RTD Ice Tea | I9: 20 | J9: 3 | K9: 0.25 | L9: Product Name | M9: RTD Ice Tea | AA9: 128
B10: Production Country | C10: ='1.1 Summary'!C9 -> Netherlands | G10: Production Country | H10: Netherlands | L10: Production Country | M10: Portugal
B11: RTD Ice Tea Machinery | C11: ='1.1 Summary'!C12 -> Fully-Automated | G11: RTD Ice Tea Machinery | H11: Fully-Automated | J11: 0.25 | L11: RTD Ice Tea Machinery | M11: Semi-Automated
B12: Facility Type | C12: ='1.1 Summary'!C13 -> New | G12: Facility Type | H12: Intermediate | J12: 0.33 | L12: Facility Type | M12: Intermediate | AA12: 1.5
B13: Product Type | C13: ='1.1 Summary'!C14 -> Non-Carbonated | G13: Product Type | H13: Non-Carbonated | J13: 0.5 | L13: Product Type | M13: Non-Carbonated | AA13: 32
B14: SKU Packing Type | C14: ='1.1 Summary'!C15 -> PET Bottle | G14: SKU Packing Type | H14: PET Bottle | J14: 1 | L14: SKU Packing Type | M14: PET Bottle
B15: SKU Size | C15: ='1.1 Summary'!C16 -> 2 | G15: SKU Size | H15: 2 | I15: Dry Aseptic | J15: France | L15: SKU Size | M15: 2
B16: Number of Units in Multipacks | C16: ='1.1 Summary'!C17 -> 6 | G16: Number of Units in Multipacks | H16: 4 | I16: Wet Aseptic | J16: Netherlands | L16: Number of Units in Multipacks | M16: 4
B17: Tray Combination | C17: ='1.1 Summary'!C18 -> 6*4 | G17: Tray Combination | H17: =IF(H16=4,"4*6",IF(H16=6,"6*4",IF(H16=8,"8*3",IF(H16=12,"12*2","24*1")))) -> 4*6 | J17: Portugal | L17: Tray Combination | M17: =IF(M16=4,"4*6",IF(M16=6,"6*4",IF(M16=8,"8*3",IF(M16=12,"12*2","24*1")))) -> 4*6
B18: PET Bottle Decontamination Process (For Can Packing, Select " – ") | C18: ='1.1 Summary'!C19 -> Dry Aseptic | G18: PET Bottle Decontamination Process (For Can Packing, Select " – ") | H18: Dry Aseptic | J18: Country B | L18: PET Bottle Decontamination Process (For Can Packing, Select " – ") | M18: Dry Aseptic
B19: Scale of Production | C19: ='1.1 Summary'!C20 -> High-scale | G19: Scale of Production | H19: High-scale | L19: Scale of Production | M19: High-scale
B20: Site Complexity | C20: ='1.1 Summary'!C21 -> Low | G20: Site Complexity | H20: Low | L20: Site Complexity | M20: Low
B22: Cost Structure Summary – Scenario 11 | G22: Cost Structure Summary – Scenario 2 | J22: 0.25 | L22: Cost Structure Summary – Scenario 3
J23: 0.33
B24: Parameters | C24: Cost Breakdown* | D24: Cost Breakdown (EUR/MT) | G24: Parameters | H24: Cost Breakdown* | I24: Cost Breakdown (EUR/MT) | J24: 0.5 | L24: Parameters | M24: Cost Breakdown* | N24: Cost Breakdown (EUR/MT)
B25: Total Equipment Cost | C25: =D25/$D$29 -> 0.023571088 | D25: ='1.1 Summary'!D28 -> 2.5086824 | G25: Total Equipment Cost | H25: =I25/$I$29 -> 0.017587103 | I25: =IF(H11="Semi-Automated",('2.1 Cost Model Processes (2)'!$E$12+'2.1 Cost Model Processes (2)'!$E$30+'2.1 Cost Model Processes (2)'!$E$48+'2.1 Cost Model Processes (2)'!$E67+'2.1 Cost Model Processes (2)'!$E86+'2.2 Cost Model Packing (2)'!$E12+'2.2 Cost Model Packing (2)'!$E32+'2.2 Cost Model Packing (2)'!$E51+'2.2 Cost Model Packing (2)'!$E70+'2.2 Cost Model Packing (2)'!$E89+'2.2 Cost Model Packing (2)'!$E108+'2.2 Cost Model Packing (2)'!$E127+'2.2 Cost Model Packing (2)'!$E146+'2.2 Cost Model Packing (2)'!$E165+'2.2 Cost Model Packing (2)'!$E184+'2.2 Cost Model Packing (2)'!$E203),('2.2 Cost Model Packing (2)'!$I203+'2.2 Cost Model Packing (2)'!$I184+'2.2 Cost Model Packing (2)'!$I165+'2.2 Cost Model Packing (2)'!$I146+'2.2 Cost Model Packing (2)'!$I127+'2.2 Cost Model Packing (2)'!$I108+'2.2 Cost Model Packing (2)'!$I89+'2.2 Cost Model Packing (2)'!$I70+'2.2 Cost Model Packing (2)'!$I51+'2.2 Cost Model Packing (2)'!$I32+'2.2 Cost Model Packing (2)'!$I12+'2.1 Cost Model Processes (2)'!$I12+'2.1 Cost Model Processes (2)'!$I30+'2.1 Cost Model Processes (2)'!$I48+'2.1 Cost Model Processes (2)'!$I67+'2.1 Cost Model Processes (2)'!$I86)) -> 1.8815118 | J25: 1 | L25: Total Equipment Cost | M25: =N25/$I$29 -> 0.019288266 | N25: =IF(M11="Semi-Automated",('2.1 Cost Model Processes (3)'!$E$12+'2.1 Cost Model Processes (3)'!$E$30+'2.1 Cost Model Processes (3)'!$E$48+'2.1 Cost Model Processes (3)'!$E67+'2.1 Cost Model Processes (3)'!$E86+'2.2 Cost Model Packing (3)'!$E12+'2.2 Cost Model Packing (3)'!$E32+'2.2 Cost Model Packing (3)'!$E51+'2.2 Cost Model Packing (3)'!$E70+'2.2 Cost Model Packing (3)'!$E89+'2.2 Cost Model Packing (3)'!$E108+'2.2 Cost Model Packing (3)'!$E127+'2.2 Cost Model Packing (3)'!$E146+'2.2 Cost Model Packing (3)'!$E165+'2.2 Cost Model Packing (3)'!$E184+'2.2 Cost Model Packing (3)'!$E203),('2.2 Cost Model Packing (3)'!$I203+'2.2 Cost Model Packing (3)'!$I184+'2.2 Cost Model Packing (3)'!$I165+'2.2 Cost Model Packing (3)'!$I146+'2.2 Cost Model Packing (3)'!$I127+'2.2 Cost Model Packing (3)'!$I108+'2.2 Cost Model Packing (3)'!$I89+'2.2 Cost Model Packing (3)'!$I70+'2.2 Cost Model Packing (3)'!$I51+'2.2 Cost Model Packing (3)'!$I32+'2.2 Cost Model Packing (3)'!$I12+'2.1 Cost Model Processes (3)'!$I12+'2.1 Cost Model Processes (3)'!$I30+'2.1 Cost Model Processes (3)'!$I48+'2.1 Cost Model Processes (3)'!$I67+'2.1 Cost Model Processes (3)'!$I86)) -> 2.0635065
B26: Total Utility Cost | C26: =D26/$D$29 -> 0.20057098 | D26: ='1.1 Summary'!D29 -> 21.346868 | G26: Total Utility Cost | H26: =I26/$I$29 -> 0.20852552 | I26: =IF(H11="Semi-Automated",('2.1 Cost Model Processes (2)'!$E17+'2.1 Cost Model Processes (2)'!$E35+'2.1 Cost Model Processes (2)'!$E53+'2.1 Cost Model Processes (2)'!$E72+'2.1 Cost Model Processes (2)'!$E91+'2.2 Cost Model Packing (2)'!$E17+'2.2 Cost Model Packing (2)'!$E37+'2.2 Cost Model Packing (2)'!$E56+'2.2 Cost Model Packing (2)'!$E75+'2.2 Cost Model Packing (2)'!$E94+'2.2 Cost Model Packing (2)'!$E113+'2.2 Cost Model Packing (2)'!$E132+'2.2 Cost Model Packing (2)'!$E151+'2.2 Cost Model Packing (2)'!$E170+'2.2 Cost Model Packing (2)'!$E189+'2.2 Cost Model Packing (2)'!$E208),('2.2 Cost Model Packing (2)'!$I208+'2.2 Cost Model Packing (2)'!$I189+'2.2 Cost Model Packing (2)'!$I170+'2.2 Cost Model Packing (2)'!$I151+'2.2 Cost Model Packing (2)'!$I132+'2.2 Cost Model Packing (2)'!$I113+'2.2 Cost Model Packing (2)'!$I94+'2.2 Cost Model Packing (2)'!$I75+'2.2 Cost Model Packing (2)'!$I56+'2.2 Cost Model Packing (2)'!$I37+'2.2 Cost Model Packing (2)'!$I17+'2.1 Cost Model Processes (2)'!$I17+'2.1 Cost Model Processes (2)'!$I35+'2.1 Cost Model Processes (2)'!$I53+'2.1 Cost Model Processes (2)'!$I72+'2.1 Cost Model Processes (2)'!$I91)) -> 22.308576 | J26: 1.5 | L26: Total Utility Cost | M26: =N26/$I$29 -> 0.30191888 | N26: =IF(M11="Semi-Automated",('2.1 Cost Model Processes (3)'!$E17+'2.1 Cost Model Processes (3)'!$E35+'2.1 Cost Model Processes (3)'!$E53+'2.1 Cost Model Processes (3)'!$E72+'2.1 Cost Model Processes (3)'!$E91+'2.2 Cost Model Packing (3)'!$E17+'2.2 Cost Model Packing (3)'!$E37+'2.2 Cost Model Packing (3)'!$E56+'2.2 Cost Model Packing (3)'!$E75+'2.2 Cost Model Packing (3)'!$E94+'2.2 Cost Model Packing (3)'!$E113+'2.2 Cost Model Packing (3)'!$E132+'2.2 Cost Model Packing (3)'!$E151+'2.2 Cost Model Packing (3)'!$E170+'2.2 Cost Model Packing (3)'!$E189+'2.2 Cost Model Packing (3)'!$E208),('2.2 Cost Model Packing (3)'!$I208+'2.2 Cost Model Packing (3)'!$I189+'2.2 Cost Model Packing (3)'!$I170+'2.2 Cost Model Packing (3)'!$I151+'2.2 Cost Model Packing (3)'!$I132+'2.2 Cost Model Packing (3)'!$I113+'2.2 Cost Model Packing (3)'!$I94+'2.2 Cost Model Packing (3)'!$I75+'2.2 Cost Model Packing (2)'!$I56+'2.2 Cost Model Packing (3)'!$I37+'2.2 Cost Model Packing (3)'!$I17+'2.1 Cost Model Processes (3)'!$I17+'2.1 Cost Model Processes (3)'!$I35+'2.1 Cost Model Processes (3)'!$I53+'2.1 Cost Model Processes (3)'!$I72+'2.1 Cost Model Processes (3)'!$I91)) -> 32.300029
B27: Total Labour Cost | C27: =D27/$D$29 -> 0.10901249 | D27: ='1.1 Summary'!D30 -> 11.602253 | G27: Total Labour Cost | H27: =I27/$I$29 -> 0.10845003 | I27: =IF(H11="Semi-Automated",('2.1 Cost Model Processes (2)'!$E24+'2.1 Cost Model Processes (2)'!$E42+'2.1 Cost Model Processes (2)'!$E60+'2.1 Cost Model Processes (2)'!$E79+'2.1 Cost Model Processes (2)'!$E98+'2.2 Cost Model Packing (2)'!$E25+'2.2 Cost Model Packing (2)'!$E45+'2.2 Cost Model Packing (2)'!$E64+'2.2 Cost Model Packing (2)'!$E83+'2.2 Cost Model Packing (2)'!$E102+'2.2 Cost Model Packing (2)'!$E121+'2.2 Cost Model Packing (2)'!$E140+'2.2 Cost Model Packing (2)'!$E159+'2.2 Cost Model Packing (2)'!$E178+'2.2 Cost Model Packing (2)'!$E197+'2.2 Cost Model Packing (2)'!$E216),('2.2 Cost Model Packing (2)'!$I216+'2.2 Cost Model Packing (2)'!$I197+'2.2 Cost Model Packing (2)'!$I178+'2.2 Cost Model Packing (2)'!$I159+'2.2 Cost Model Packing (2)'!$I140+'2.2 Cost Model Packing (2)'!$I121+'2.2 Cost Model Packing (2)'!$I102+'2.2 Cost Model Packing (2)'!$I83+'2.2 Cost Model Packing (2)'!$I64+'2.2 Cost Model Packing (2)'!$I45+'2.2 Cost Model Packing (2)'!$I25+'2.1 Cost Model Processes (2)'!I98+'2.1 Cost Model Processes (2)'!$I79+'2.1 Cost Model Processes (2)'!$I60+'2.1 Cost Model Processes (2)'!$I42+'2.1 Cost Model Processes (2)'!$I24)) -> 11.602253 | J27: 2 | L27: Total Labour Cost | M27: =N27/$I$29 -> 0.15868962 | N27: =IF(M11="Semi-Automated",('2.1 Cost Model Processes (3)'!$E24+'2.1 Cost Model Processes (3)'!$E42+'2.1 Cost Model Processes (3)'!$E60+'2.1 Cost Model Processes (3)'!$E79+'2.1 Cost Model Processes (3)'!$E98+'2.2 Cost Model Packing (3)'!$E25+'2.2 Cost Model Packing (3)'!$E45+'2.2 Cost Model Packing (3)'!$E64+'2.2 Cost Model Packing (3)'!$E83+'2.2 Cost Model Packing (3)'!$E102+'2.2 Cost Model Packing (3)'!$E121+'2.2 Cost Model Packing (3)'!$E140+'2.2 Cost Model Packing (3)'!$E159+'2.2 Cost Model Packing (3)'!$E178+'2.2 Cost Model Packing (3)'!$E197+'2.2 Cost Model Packing (3)'!$E216),('2.2 Cost Model Packing (3)'!$I216+'2.2 Cost Model Packing (3)'!$I197+'2.2 Cost Model Packing (3)'!$I178+'2.2 Cost Model Packing (3)'!$I159+'2.2 Cost Model Packing (3)'!$I140+'2.2 Cost Model Packing (3)'!$I121+'2.2 Cost Model Packing (3)'!$I102+'2.2 Cost Model Packing (3)'!$I83+'2.2 Cost Model Packing (3)'!$I64+'2.2 Cost Model Packing (3)'!$I45+'2.2 Cost Model Packing (3)'!$I25+'2.1 Cost Model Processes (3)'!N98+'2.1 Cost Model Processes (3)'!$I79+'2.1 Cost Model Processes (3)'!$I60+'2.1 Cost Model Processes (3)'!$I42+'2.1 Cost Model Processes (3)'!$I24)) -> 16.977009
B28: Total Overhead and Indirect Cost | C28: =D28/$D$29 -> 0.66684544 | D28: ='1.1 Summary'!D31 -> 70.972686 | G28: Total Overhead and Indirect Cost | H28: =I28/$I$29 -> 0.66543735 | I28: =IF(H11="Semi-Automated",('2.1 Cost Model Processes (2)'!$E115+'2.2 Cost Model Packing (2)'!$E232),('2.2 Cost Model Packing (2)'!$I232+'2.1 Cost Model Processes (2)'!$I115)) -> 71.190136 | L28: Total Overhead and Indirect Cost | M28: =N28/$I$29 -> 0.96769662 | N28: =IF(M11="Semi-Automated",('2.1 Cost Model Processes (3)'!$E115+'2.2 Cost Model Packing (3)'!$E232),('2.2 Cost Model Packing (3)'!$I232+'2.1 Cost Model Processes (3)'!$I115)) -> 103.52658
B29: Total Production Cost | C29: =SUM(C25:C28) -> 1 | D29: =SUM(D25:D28) -> 106.43049 | G29: Total Production Cost | H29: =SUM(H25:H28) -> 1 | I29: =SUM(I25:I28) -> 106.98248 | L29: Total Production Cost | M29: =SUM(M25:M28) -> 1.4475934 | N29: =SUM(N25:N28) -> 154.86712
B31: Average Margins Earned by Supplier | C31: Low | D31: =IF(C31="High",20%,IF(C31="Medium",15%,10%)) -> 0.1 | E31: Please click for definition | G31: Average Margins Earned by Supplier | H31: Medium | I31: =IF(H31="High",20%,IF(H31="Medium",15%,10%)) -> 0.15 | L31: Average Margins Earned by Supplier | M31: Medium | N31: =IF(M31="High",20%,IF(M31="Medium",15%,10%)) -> 0.15
B32: Production Cost including Margin Earned by Supplier | D32: =(D31*D29)+D29 -> 117.07354 | G32: Production Cost including Margin Earned by Supplier | I32: =(I31*I29)+I29 -> 123.02985 | L32: Production Cost including Margin Earned by Supplier | N32: =(N31*N29)+N29 -> 178.09719
B34: Purchase Price ($/MT) | D34: 321 | G34: Purchase Price ($/MT) | I34: 321 | L34: Purchase Price ($/MT) | N34: 321
B36: Gap (EUR/MT) | D36: =IF(D34="","Please enter purchase price in cell D32",D34-D32) -> 203.92646 | G36: Gap (EUR/MT) | I36: =IF(I34="","Please enter purchase price in cell D32",I34-I32) -> 197.97015 | L36: Gap (EUR/MT) | N36: =IF(N34="","Please enter purchase price in cell D32",N34-N32) -> 142.90281
B37: Cost Structure Summary-Scenario 1 | G37: Cost Structure Summary-Scenario 2 | L37: Cost Structure Summary-Scenario 3
B49: Note:
B50: 1) Inputs are drawn from 1.1 Summary sheet. Any changes made in the summary sheet will be reflected in the scenario 1
A51: Copyright © 2026 WNS (Holdings) Ltd. All rights reserved.
B142: ='[9]1.1 Summary'!B37 -> Cost Breakdown – Processes – By Cost Type
B143: ='1.2 Scenario Analysis'!#REF! -> #REF!

Sheet Part 2 - Cost Breakdown

Sheet 2.1 Cost Model Processes
C5: Summary – Process Cost
D7: Semi-Automatic | H7: Automatic
B9: Water Treatment Process | C9: Water Treatment
C10: Machinery | D10: Total Hourly Cost (€) | E10: Total Depreciation per MT (€/MT) | F10: Percentage of the Total Cost (%) | H10: Total Hourly Cost (€) | I10: Total Depreciation per MT (€/MT) | J10: Percentage of the Total Cost (%)
C11: Reverse Osmosis Water Treatment Machine | D11: ='3.1 Water Treatment'!F34 -> 1.2239583 | E11: ='3.1 Water Treatment'!G34 -> 0.52811352 | F11: =D11/$D$118 -> 0.0074909111 | H11: ='3.1 Water Treatment'!F38 -> 1.4583333 | I11: ='3.1 Water Treatment'!G38 -> 0.41537458 | J11: =H11/$H$118 -> 0.0083080903
C12: Total Machinery Cost | D12: =SUM(D11:D11) -> 1.2239583 | E12: =SUM(E11:E11) -> 0.52811352 | F12: =SUM(F11:F11) -> 0.0074909111 | H12: =SUM(H11:H11) -> 1.4583333 | I12: =SUM(I11:I11) -> 0.41537458 | J12: =SUM(J11:J11) -> 0.0083080903
C14: Utility | D14: Total Hourly Cost (€) | E14: Total Cost per MT (€/MT) | F14: Percentage of the Total Cost (%) | H14: Total Hourly Cost (€) | I14: Total Cost per MT (€/MT) | J14: Percentage of the Total Cost (%)
C15: Electricity and Natural Gas Cost | D15: ='3.1 Water Treatment'!F44 -> 7.4631322 | E15: ='3.1 Water Treatment'!G44 -> 3.2201922 | F15: =D15/$D$118 -> 0.045676114 | H15: ='3.1 Water Treatment'!F48 -> 8.3290301 | I15: ='3.1 Water Treatment'!G48 -> 2.3723434 | J15: =H15/$H$118 -> 0.047450287
C16: Other Utility Cost | D16: =15%*D15 -> 1.1194698 | E16: =15%*E15 -> 0.48302882 | F16: =D16/$D$118 -> 0.006851417 | H16: =15%*H15 -> 1.2493545 | I16: =15%*I15 -> 0.3558515 | J16: =H16/$H$118 -> 0.007117543
C17: Total Utility Cost | D17: =SUM(D15:D16) -> 8.582602 | E17: =SUM(E15:E16) -> 3.703221 | F17: =SUM(F15:F16) -> 0.052527531 | H17: =SUM(H15:H16) -> 9.5783847 | I17: =SUM(I15:I16) -> 2.7281949 | J17: =SUM(J15:J16) -> 0.05456783
C19: Labour Cost | D19: Total Hourly Cost (€) | E19: Total Cost per MT (€/MT) | F19: Percentage of the Total Cost (%) | H19: Total Hourly Cost (€) | I19: Total Cost per MT (€/MT) | J19: Percentage of the Total Cost (%)
C20: Production Manager | D20: ='3.1 Water Treatment'!F53 -> 2.2505195 | E20: ='3.1 Water Treatment'!G53 -> 0.9710541 | F20: =D20/$D$118 -> 0.013773705 | H20: ='3.1 Water Treatment'!F60 -> 2.2505195 | I20: ='3.1 Water Treatment'!G60 -> 0.64101159 | J20: =H20/$H$118 -> 0.012821156
C21: Shift Supervisor | D21: ='3.1 Water Treatment'!F54 -> 1.8653017 | E21: ='3.1 Water Treatment'!G54 -> 0.80484035 | F21: =D21/$D$118 -> 0.011416082 | H21: ='3.1 Water Treatment'!F61 -> 1.8653017 | I21: ='3.1 Water Treatment'!G61 -> 0.53129068 | J21: =H21/$H$118 -> 0.010626579
C22: Machine Operator | D22: ='3.1 Water Treatment'!F55 -> 1.1616204 | E22: ='3.1 Water Treatment'!G55 -> 0.50121597 | F22: =D22/$D$118 -> 0.0071093886 | H22: ='3.1 Water Treatment'!F62 -> 1.1616204 | I22: ='3.1 Water Treatment'!G62 -> 0.33086236 | J22: =H22/$H$118 -> 0.006617724
C23: Production Worker | D23: ='3.1 Water Treatment'!F56 -> 2.214619 | E23: ='3.1 Water Treatment'!G56 -> 0.95556378 | F23: =D23/$D$118 -> 0.013553986 | H23: ='3.1 Water Treatment'!F63 -> 2.214619 | I23: ='3.1 Water Treatment'!G63 -> 0.63078613 | J23: =H23/$H$118 -> 0.012616632
C24: Total labor Cost | D24: =SUM(D20:D23) -> 7.4920606 | E24: =SUM(E20:E23) -> 3.2326742 | F24: =SUM(F20:F23) -> 0.045853162 | H24: =SUM(H20:H23) -> 7.4920606 | I24: =SUM(I20:I23) -> 2.1339508 | J24: =SUM(J20:J23) -> 0.042682091
C25: Total Water Treatment Process Costs | D25: =SUM(D12,D17,D24) -> 17.298621 | E25: =SUM(E12,E17,E24) -> 7.4640087 | F25: =SUM(F17,F12,F24) -> 0.1058716 | H25: =SUM(H17,H12,H24) -> 18.528779 | I25: =SUM(I17,I12,I24) -> 5.2775202 | J25: =SUM(J24+J12+J17) -> 0.10555801
B27: Syrup Preparation Process | C27: Syrup Preparation
C28: Machinery | D28: Total Hourly Cost (€) | E28: Total Depreciation per MT (€/MT) | F28: Percentage of the Total Cost (%) | H28: Total Hourly Cost (€) | I28: Total Depreciation per MT (€/MT) | J28: Percentage of the Total Cost (%)
C29: Jacket Mixing Tank with High Shear Mixer | D29: ='3.2 Syrup Preparation'!F34 -> 0.15625 | E29: ='3.2 Syrup Preparation'!G34 -> 0.079261027 | F29: =D29/$D$118 -> 0.00095628653 | H29: ='3.2 Syrup Preparation'!F38 -> 1.7708333 | I29: ='3.2 Syrup Preparation'!G38 -> 0.61568158 | J29: =H29/$H$118 -> 0.010088395
C30: Total Machinery Cost | D30: =SUM(D29:D29) -> 0.15625 | E30: =SUM(E29:E29) -> 0.079261027 | F30: =SUM(F29:F29) -> 0.00095628653 | H30: =SUM(H29:H29) -> 1.7708333 | I30: =SUM(I29:I29) -> 0.61568158 | J30: =SUM(J29:J29) -> 0.010088395
C32: Utility | D32: Total Hourly Cost (€) | E32: Total Cost per MT (€/MT) | F32: Percentage of the Total Cost (%) | H32: Total Hourly Cost (€) | I32: Total Cost per MT (€/MT) | J32: Percentage of the Total Cost (%)
C33: Electricity and Natural Gas Cost | D33: ='3.2 Syrup Preparation'!F44 -> 9.8305567 | E33: ='3.2 Syrup Preparation'!G44 -> 4.9867521 | F33: =D33/$D$118 -> 0.060165305 | H33: ='3.2 Syrup Preparation'!F48 -> 10.619698 | I33: ='3.2 Syrup Preparation'!G48 -> 3.6922462 | J33: =H33/$H$118 -> 0.060500168
C34: Other Utility Cost | D34: =15%*D33 -> 1.4745835 | E34: =15%*E33 -> 0.74801282 | F34: =D34/$D$118 -> 0.0090247958 | H34: =15%*H33 -> 1.5929547 | I34: =15%*I33 -> 0.55383693 | J34: =H34/$H$118 -> 0.0090750252
C35: Total Utility Cost | D35: =SUM(D33:D34) -> 11.30514 | E35: =SUM(E33:E34) -> 5.7347649 | F35: =SUM(F33:F34) -> 0.069190101 | H35: =SUM(H33:H34) -> 12.212653 | I35: =SUM(I33:I34) -> 4.2460831 | J35: =SUM(J33:J34) -> 0.069575194
C37: Labour Cost | D37: Total Hourly Cost (€) | E37: Total Cost per MT (€/MT) | F37: Percentage of the Total Cost (%) | H37: Total Hourly Cost (€) | I37: Total Cost per MT (€/MT) | J37: Percentage of the Total Cost (%)
C38: Production Manager | D38: ='3.2 Syrup Preparation'!F53 -> 2.2505195 | E38: ='3.2 Syrup Preparation'!G53 -> 1.1416223 | F38: =D38/$D$118 -> 0.013773705 | H38: ='3.2 Syrup Preparation'!F60 -> 2.2505195 | I38: ='3.2 Syrup Preparation'!G60 -> 0.78245838 | J38: =H38/$H$118 -> 0.012821156
C39: Shift Supervisor | D39: ='3.2 Syrup Preparation'!F54 -> 1.8653017 | E39: ='3.2 Syrup Preparation'!G54 -> 0.94621266 | F39: =D39/$D$118 -> 0.011416082 | H39: ='3.2 Syrup Preparation'!F61 -> 1.8653017 | I39: ='3.2 Syrup Preparation'!G61 -> 0.64852625 | J39: =H39/$H$118 -> 0.010626579
C40: Machine Operator | D40: ='3.2 Syrup Preparation'!F55 -> 1.1616204 | E40: ='3.2 Syrup Preparation'!G55 -> 0.58925586 | F40: =D40/$D$118 -> 0.0071093886 | H40: ='3.2 Syrup Preparation'!F62 -> 2.3232409 | I40: ='3.2 Syrup Preparation'!G62 -> 0.8077421 | J40: =H40/$H$118 -> 0.013235448
C41: Production Worker | D41: ='3.2 Syrup Preparation'!F56 -> 2.214619 | E41: ='3.2 Syrup Preparation'!G56 -> 1.1234111 | F41: =D41/$D$118 -> 0.013553986 | H41: ='3.2 Syrup Preparation'!F63 -> 2.214619 | I41: ='3.2 Syrup Preparation'!G63 -> 0.76997655 | J41: =H41/$H$118 -> 0.012616632
C42: Total labor Cost | D42: =SUM(D38:D41) -> 7.4920606 | E42: =SUM(E38:E41) -> 3.8005019 | F42: =SUM(F38:F41) -> 0.045853162 | H42: =SUM(H38:H41) -> 8.6536811 | I42: =SUM(I38:I41) -> 3.0087033 | J42: =SUM(J38:J41) -> 0.049299815
C43: Total Syrup Preparation Process Costs | D43: =SUM(D30,D35,D42) -> 18.953451 | E43: =SUM(E30,E35,E42) -> 9.6145278 | F43: =SUM(F42,F30,F35) -> 0.11599955 | H43: =SUM(H42,H35,H30) -> 22.637167 | I43: =SUM(I42,I35,I30) -> 7.870468 | J43: =SUM(J30,J35,J42) -> 0.1289634
B45: Mixing Process | C45: Mixing Process
C46: Machinery | D46: Total Hourly Cost (€) | E46: Total Depreciation per MT (€/MT) | F46: Percentage of the Total Cost (%) | H46: Total Hourly Cost (€) | I46: Total Depreciation per MT (€/MT) | J46: Percentage of the Total Cost (%)
C47: Pressure Blending Tank | D47: ='3.4 Mixing'!F34 -> 1.0416667 | E47: ='3.4 Mixing'!G34 -> 0.16001417 | F47: =D47/$D$118 -> 0.0063752435 | H47: ='3.4 Mixing'!F38 -> 1.2239583 | I47: ='3.4 Mixing'!G38 -> 0.065912423 | J47: =H47/$H$118 -> 0.0069728615
C48: Total Machinery Cost | D48: =SUM(D47) -> 1.0416667 | E48: =SUM(E47) -> 0.16001417 | F48: =SUM(F47:F47) -> 0.0063752435 | H48: =SUM(H47:H47) -> 1.2239583 | I48: =SUM(I47:I47) -> 0.065912423 | J48: =SUM(J47:J47) -> 0.0069728615
C50: Utility | D50: Total Hourly Cost (€) | E50: Total Cost per MT (€/MT) | F50: Percentage of the Total Cost (%) | H50: Total Hourly Cost (€) | I50: Total Cost per MT (€/MT) | J50: Percentage of the Total Cost (%)
C51: Electricity and Natural Gas Cost | D51: ='3.4 Mixing'!F44 -> 3.5174246 | E51: ='3.4 Mixing'!G44 -> 0.54032426 | F51: =D51/$D$118 -> 0.021527461 | H51: ='3.4 Mixing'!F48 -> 4.3065661 | I51: ='3.4 Mixing'!G48 -> 0.23191656 | J51: =H51/$H$118 -> 0.024534405
C52: Other Utility Cost | D52: =15%*D51 -> 0.52761368 | E52: =15%*E51 -> 0.081048639 | F52: =D52/$D$118 -> 0.0032291191 | H52: =15%*H51 -> 0.64598491 | I52: =15%*I51 -> 0.034787484 | J52: =H52/$H$118 -> 0.0036801607
C53: Total Utility Cost | D53: =SUM(D51:D52) -> 4.0450383 | E53: =SUM(E51:E52) -> 0.6213729 | F53: =SUM(F51:F52) -> 0.02475658 | H53: =SUM(H51:H52) -> 4.952551 | I53: =SUM(I51:I52) -> 0.26670404 | J53: =SUM(J51:J52) -> 0.028214565
...

Sheet 2.1 Cost Model Processes (2)
C5: Summary – Process Cost
D7: Semi-Automatic | H7: Automatic
B9: Water Treatment Process | C9: Water Treatment
C10: Machinery | D10: Total Hourly Cost (€) | E10: Total Depreciation per MT (€/MT) | F10: Percentage of the Total Cost (%) | H10: Total Hourly Cost (€) | I10: Total Depreciation per MT (€/MT) | J10: Percentage of the Total Cost (%)
C11: Reverse Osmosis Water Treatment Machine | D11: ='3.1 Water Treatment (2)'!F33 -> 0.91796875 | E11: ='3.1 Water Treatment (2)'!G33 -> 0.39608514 | F11: =D11/$D$118 -> 0.0055621048 | H11: ='3.1 Water Treatment (2)'!F37 -> 1.09375 | I11: ='3.1 Water Treatment (2)'!G37 -> 0.31153093 | J11: =H11/$H$118 -> 0.0061895902
C12: Total Machinery Cost | D12: =SUM(D11:D11) -> 0.91796875 | E12: =SUM(E11:E11) -> 0.39608514 | F12: =SUM(F11:F11) -> 0.0055621048 | H12: =SUM(H11:H11) -> 1.09375 | I12: =SUM(I11:I11) -> 0.31153093 | J12: =SUM(J11:J11) -> 0.0061895902
C14: Utility | D14: Total Hourly Cost (€) | E14: Total Cost per MT (€/MT) | F14: Percentage of the Total Cost (%) | H14: Total Hourly Cost (€) | I14: Total Cost per MT (€/MT) | J14: Percentage of the Total Cost (%)
C15: Electricity and Natural Gas Cost | D15: ='3.1 Water Treatment (2)'!F44 -> 7.9681827 | E15: ='3.1 Water Treatment (2)'!G44 -> 3.4381114 | F15: =D15/$D$118 -> 0.048280366 | H15: ='3.1 Water Treatment (2)'!F48 -> 8.897212 | I15: ='3.1 Water Treatment (2)'!G48 -> 2.5341776 | J15: =H15/$H$118 -> 0.050349802
C16: Other Utility Cost | D16: =15%*D15 -> 1.1952274 | E16: =15%*E15 -> 0.51571671 | F16: =D16/$D$118 -> 0.0072420549 | H16: =15%*H15 -> 1.3345818 | I16: =15%*I15 -> 0.38012664 | J16: =H16/$H$118 -> 0.0075524703
C17: Total Utility Cost | D17: =SUM(D15:D16) -> 9.1634102 | E17: =SUM(E15:E16) -> 3.9538281 | F17: =SUM(F15:F16) -> 0.055522421 | H17: =SUM(H15:H16) -> 10.231794 | I17: =SUM(I15:I16) -> 2.9143043 | J17: =SUM(J15:J16) -> 0.057902272
C19: Labour Cost | D19: Total Hourly Cost (€) | E19: Total Cost per MT (€/MT) | F19: Percentage of the Total Cost (%) | H19: Total Hourly Cost (€) | I19: Total Cost per MT (€/MT) | J19: Percentage of the Total Cost (%)
C20: Production Manager | D20: ='3.1 Water Treatment (2)'!F53 -> 2.2505195 | E20: ='3.1 Water Treatment (2)'!G53 -> 0.9710541 | F20: =D20/$D$118 -> 0.013636221 | H20: ='3.1 Water Treatment (2)'!F60 -> 2.2505195 | I20: ='3.1 Water Treatment (2)'!G60 -> 0.64101159 | J20: =H20/$H$118 -> 0.012735811
C21: Shift Supervisor | D21: ='3.1 Water Treatment (2)'!F54 -> 1.8653017 | E21: ='3.1 Water Treatment (2)'!G54 -> 0.80484035 | F21: =D21/$D$118 -> 0.011302132 | H21: ='3.1 Water Treatment (2)'!F61 -> 1.8653017 | I21: ='3.1 Water Treatment (2)'!G61 -> 0.53129068 | J21: =H21/$H$118 -> 0.010555843
C22: Machine Operator | D22: ='3.1 Water Treatment (2)'!F55 -> 1.1616204 | E22: ='3.1 Water Treatment (2)'!G55 -> 0.50121597 | F22: =D22/$D$118 -> 0.0070384255 | H22: ='3.1 Water Treatment (2)'!F62 -> 1.1616204 | I22: ='3.1 Water Treatment (2)'!G62 -> 0.33086236 | J22: =H22/$H$118 -> 0.0065736726
C23: Production Worker | D23: ='3.1 Water Treatment (2)'!F56 -> 2.214619 | E23: ='3.1 Water Treatment (2)'!G56 -> 0.95556378 | F23: =D23/$D$118 -> 0.013418695 | H23: ='3.1 Water Treatment (2)'!F63 -> 2.214619 | I23: ='3.1 Water Treatment (2)'!G63 -> 0.63078613 | J23: =H23/$H$118 -> 0.012532648
C24: Total labor Cost | D24: =SUM(D20:D23) -> 7.4920606 | E24: =SUM(E20:E23) -> 3.2326742 | F24: =SUM(F20:F23) -> 0.045395474 | H24: =SUM(H20:H23) -> 7.4920606 | I24: =SUM(I20:I23) -> 2.1339508 | J24: =SUM(J20:J23) -> 0.042397975
C25: Total Water Treatment Process Costs | D25: =SUM(D12,D17,D24) -> 17.57344 | E25: =SUM(E12,E17,E24) -> 7.5825874 | F25: =SUM(F17,F12,F24) -> 0.10648 | H25: =SUM(H17,H12,H24) -> 18.817604 | I25: =SUM(I17,I12,I24) -> 5.359786 | J25: =SUM(J24+J12+J17) -> 0.10648984
B27: Syrup Preparation Process | C27: Syrup Preparation
C28: Machinery | D28: Total Hourly Cost (€) | E28: Total Depreciation per MT (€/MT) | F28: Percentage of the Total Cost (%) | H28: Total Hourly Cost (€) | I28: Total Depreciation per MT (€/MT) | J28: Percentage of the Total Cost (%)
C29: Jacket Mixing Tank with High Shear Mixer | D29: ='3.2 Syrup Preparation (2)'!F33 -> 0.1171875 | E29: ='3.2 Syrup Preparation (2)'!G33 -> 0.05944577 | F29: =D29/$D$118 -> 0.00071005593 | H29: ='3.2 Syrup Preparation (2)'!F38 -> 1.328125 | I29: ='3.2 Syrup Preparation (2)'!G38 -> 0.46176119 | J29: =H29/$H$118 -> 0.0075159309
C30: Total Machinery Cost | D30: =SUM(D29:D29) -> 0.1171875 | E30: =SUM(E29:E29) -> 0.05944577 | F30: =SUM(F29:F29) -> 0.00071005593 | H30: =SUM(H29:H29) -> 1.328125 | I30: =SUM(I29:I29) -> 0.46176119 | J30: =SUM(J29:J29) -> 0.0075159309
C32: Utility | D32: Total Hourly Cost (€) | E32: Total Cost per MT (€/MT) | F32: Percentage of the Total Cost (%) | H32: Total Hourly Cost (€) | I32: Total Cost per MT (€/MT) | J32: Percentage of the Total Cost (%)
C33: Electricity and Natural Gas Cost | D33: ='3.2 Syrup Preparation (2)'!F44 -> 10.525001 | E33: ='3.2 Syrup Preparation (2)'!G44 -> 5.3390234 | F33: =D33/$D$118 -> 0.063772498 | H33: ='3.2 Syrup Preparation (2)'!F48 -> 11.377274 | I33: ='3.2 Syrup Preparation (2)'!G48 -> 3.9556394 | J33: =H33/$H$118 -> 0.064384607
C34: Other Utility Cost | D34: =15%*D33 -> 1.5787502 | E34: =15%*E33 -> 0.80085351 | F34: =D34/$D$118 -> 0.0095658747 | H34: =15%*H33 -> 1.7065911 | I34: =15%*I33 -> 0.59334591 | J34: =H34/$H$118 -> 0.009657691
C35: Total Utility Cost | D35: =SUM(D33:D34) -> 12.103751 | E35: =SUM(E33:E34) -> 6.1398769 | F35: =SUM(F33:F34) -> 0.073338373 | H35: =SUM(H33:H34) -> 13.083865 | I35: =SUM(I33:I34) -> 4.5489853 | J35: =SUM(J33:J34) -> 0.074042298
C37: Labour Cost | D37: Total Hourly Cost (€) | E37: Total Cost per MT (€/MT) | F37: Percentage of the Total Cost (%) | H37: Total Hourly Cost (€) | I37: Total Cost per MT (€/MT) | J37: Percentage of the Total Cost (%)
C38: Production Manager | D38: ='3.2 Syrup Preparation (2)'!F53 -> 2.2505195 | E38: ='3.2 Syrup Preparation (2)'!G53 -> 1.1416223 | F38: =D38/$D$118 -> 0.013636221 | H38: ='3.2 Syrup Preparation (2)'!F60 -> 2.2505195 | I38: ='3.2 Syrup Preparation (2)'!G60 -> 0.78245838 | J38: =H38/$H$118 -> 0.012735811
C39: Shift Supervisor | D39: ='3.2 Syrup Preparation (2)'!F54 -> 1.8653017 | E39: ='3.2 Syrup Preparation (2)'!G54 -> 0.94621266 | F39: =D39/$D$118 -> 0.011302132 | H39: ='3.2 Syrup Preparation (2)'!F61 -> 1.8653017 | I39: ='3.2 Syrup Preparation (2)'!G61 -> 0.64852625 | J39: =H39/$H$118 -> 0.010555843
C40: Machine Operator | D40: ='3.2 Syrup Preparation (2)'!F55 -> 1.1616204 | E40: ='3.2 Syrup Preparation (2)'!G55 -> 0.58925586 | F40: =D40/$D$118 -> 0.0070384255 | H40: ='3.2 Syrup Preparation (2)'!F62 -> 2.3232409 | I40: ='3.2 Syrup Preparation (2)'!G62 -> 0.8077421 | J40: =H40/$H$118 -> 0.013147345
C41: Production Worker | D41: ='3.2 Syrup Preparation (2)'!F56 -> 2.214619 | E41: ='3.2 Syrup Preparation (2)'!G56 -> 1.1234111 | F41: =D41/$D$118 -> 0.013418695 | H41: ='3.2 Syrup Preparation (2)'!F63 -> 2.214619 | I41: ='3.2 Syrup Preparation (2)'!G63 -> 0.76997655 | J41: =H41/$H$118 -> 0.012532648
C42: Total labor Cost | D42: =SUM(D38:D41) -> 7.4920606 | E42: =SUM(E38:E41) -> 3.8005019 | F42: =SUM(F38:F41) -> 0.045395474 | H42: =SUM(H38:H41) -> 8.6536811 | I42: =SUM(I38:I41) -> 3.0087033 | J42: =SUM(J38:J41) -> 0.048971647
C43: Total Syrup Preparation Process Costs | D43: =SUM(D30,D35,D42) -> 19.713 | E43: =SUM(E30,E35,E42) -> 9.9998246 | F43: =SUM(F42,F30,F35) -> 0.1194439 | H43: =SUM(H42,H35,H30) -> 23.065671 | I43: =SUM(I42,I35,I30) -> 8.0194498 | J43: =SUM(J30,J35,J42) -> 0.13052988
B45: Mixing Process | C45: Mixing Process
C46: Machinery | D46: Total Hourly Cost (€) | E46: Total Depreciation per MT (€/MT) | F46: Percentage of the Total Cost (%) | H46: Total Hourly Cost (€) | I46: Total Depreciation per MT (€/MT) | J46: Percentage of the Total Cost (%)
C47: Pressure Blending Tank | D47: ='3.4 Mixing (2)'!F33 -> 0.78125 | E47: ='3.4 Mixing (2)'!G33 -> 0.12001063 | F47: =D47/$D$118 -> 0.0047337062 | H47: ='3.4 Mixing (2)'!F38 -> 0.91796875 | I47: ='3.4 Mixing (2)'!G38 -> 0.049434317 | J47: =H47/$H$118 -> 0.0051948346
C48: Total Machinery Cost | D48: =SUM(D47) -> 0.78125 | E48: =SUM(E47) -> 0.12001063 | F48: =SUM(F47:F47) -> 0.0047337062 | H48: =SUM(H47:H47) -> 0.91796875 | I48: =SUM(I47:I47) -> 0.049434317 | J48: =SUM(J47:J47) -> 0.0051948346
C50: Utility | D50: Total Hourly Cost (€) | E50: Total Cost per MT (€/MT) | F50: Percentage of the Total Cost (%) | H50: Total Hourly Cost (€) | I50: Total Cost per MT (€/MT) | J50: Percentage of the Total Cost (%)
C51: Electricity and Natural Gas Cost | D51: ='3.4 Mixing (2)'!F44 -> 3.7068185 | E51: ='3.4 Mixing (2)'!G44 -> 0.56941775 | F51: =D51/$D$118 -> 0.022460147 | H51: ='3.4 Mixing (2)'!F48 -> 4.5590914 | I51: ='3.4 Mixing (2)'!G48 -> 0.24551551 | J51: =H51/$H$118 -> 0.025800144
C52: Other Utility Cost | D52: =15%*D51 -> 0.55602278 | E52: =15%*E51 -> 0.085412662 | F52: =D52/$D$118 -> 0.0033690221 | H52: =15%*H51 -> 0.68386371 | I52: =15%*I51 -> 0.036827327 | J52: =H52/$H$118 -> 0.0038700215
C53: Total Utility Cost | D53: =SUM(D51:D52) -> 4.2628413 | E53: =SUM(E51:E52) -> 0.65483041 | F53: =SUM(F51:F52) -> 0.025829169 | H53: =SUM(H51:H52) -> 5.2429551 | I53: =SUM(I51:I52) -> 0.28234284 | J53: =SUM(J51:J52) -> 0.029670165
...

Sheet 2.1 Cost Model Processes (3)
C5: Summary – Process Cost
D7: Semi-Automatic | H7: Automatic
B9: Water Treatment Process | C9: Water Treatment
C10: Machinery | D10: Total Hourly Cost (€) | E10: Total Depreciation per MT (€/MT) | F10: Percentage of the Total Cost (%) | H10: Total Hourly Cost (€) | I10: Total Depreciation per MT (€/MT) | J10: Percentage of the Total Cost (%)
C11: Reverse Osmosis Water Treatment Machine | D11: ='3.1 Water Treatment (3)'!F33 -> 0.91796875 | E11: ='3.1 Water Treatment (3)'!G33 -> 0.39608514 | F11: =D11/$D$118 -> 0.0055649051 | H11: ='3.1 Water Treatment (3)'!F37 -> 1.09375 | I11: ='3.1 Water Treatment (3)'!G37 -> 0.31153093 | J11: =H11/$H$118 -> 0.0061925005
C12: Total Machinery Cost | D12: =SUM(D11:D11) -> 0.91796875 | E12: =SUM(E11:E11) -> 0.39608514 | F12: =SUM(F11:F11) -> 0.0055649051 | H12: =SUM(H11:H11) -> 1.09375 | I12: =SUM(I11:I11) -> 0.31153093 | J12: =SUM(J11:J11) -> 0.0061925005
C14: Utility | D14: Total Hourly Cost (€) | E14: Total Cost per MT (€/MT) | F14: Percentage of the Total Cost (%) | H14: Total Hourly Cost (€) | I14: Total Cost per MT (€/MT) | J14: Percentage of the Total Cost (%)
C15: Electricity and Natural Gas Cost | D15: ='3.1 Water Treatment (3)'!F44 -> 7.9681827 | E15: ='3.1 Water Treatment (3)'!G44 -> 3.4381114 | F15: =D15/$D$118 -> 0.048304674 | H15: ='3.1 Water Treatment (3)'!F48 -> 8.897212 | I15: ='3.1 Water Treatment (3)'!G48 -> 2.5341776 | J15: =H15/$H$118 -> 0.050373477
C16: Other Utility Cost | D16: =15%*D15 -> 1.1952274 | E16: =15%*E15 -> 0.51571671 | F16: =D16/$D$118 -> 0.0072457011 | H16: =15%*H15 -> 1.3345818 | I16: =15%*I15 -> 0.38012664 | J16: =H16/$H$118 -> 0.0075560215
C17: Total Utility Cost | D17: =SUM(D15:D16) -> 9.1634102 | E17: =SUM(E15:E16) -> 3.9538281 | F17: =SUM(F15:F16) -> 0.055550375 | H17: =SUM(H15:H16) -> 10.231794 | I17: =SUM(I15:I16) -> 2.9143043 | J17: =SUM(J15:J16) -> 0.057929498
C19: Labour Cost | D19: Total Hourly Cost (€) | E19: Total Cost per MT (€/MT) | F19: Percentage of the Total Cost (%) | H19: Total Hourly Cost (€) | I19: Total Cost per MT (€/MT) | J19: Percentage of the Total Cost (%)
C20: Production Manager | D20: ='3.1 Water Treatment (3)'!F53 -> 2.2505195 | E20: ='3.1 Water Treatment (3)'!G53 -> 0.9710541 | F20: =D20/$D$118 -> 0.013643087 | H20: ='3.1 Water Treatment (3)'!F60 -> 2.2505195 | I20: ='3.1 Water Treatment (3)'!G60 -> 0.64101159 | J20: =H20/$H$118 -> 0.012741799
C21: Shift Supervisor | D21: ='3.1 Water Treatment (3)'!F54 -> 1.8653017 | E21: ='3.1 Water Treatment (3)'!G54 -> 0.80484035 | F21: =D21/$D$118 -> 0.011307822 | H21: ='3.1 Water Treatment (3)'!F61 -> 1.8653017 | I21: ='3.1 Water Treatment (3)'!G61 -> 0.53129068 | J21: =H21/$H$118 -> 0.010560806
C22: Machine Operator | D22: ='3.1 Water Treatment (3)'!F55 -> 1.1616204 | E22: ='3.1 Water Treatment (3)'!G55 -> 0.50121597 | F22: =D22/$D$118 -> 0.0070419691 | H22: ='3.1 Water Treatment (3)'!F62 -> 1.1616204 | I22: ='3.1 Water Treatment (3)'!G62 -> 0.33086236 | J22: =H22/$H$118 -> 0.0065767636
C23: Production Worker | D23: ='3.1 Water Treatment (3)'!F56 -> 2.214619 | E23: ='3.1 Water Treatment (3)'!G56 -> 0.95556378 | F23: =D23/$D$118 -> 0.013425451 | H23: ='3.1 Water Treatment (3)'!F63 -> 2.214619 | I23: ='3.1 Water Treatment (3)'!G63 -> 0.63078613 | J23: =H23/$H$118 -> 0.012538541
C24: Total labor Cost | D24: =SUM(D20:D23) -> 7.4920606 | E24: =SUM(E20:E23) -> 3.2326742 | F24: =SUM(F20:F23) -> 0.045418329 | H24: =SUM(H20:H23) -> 7.4920606 | I24: =SUM(I20:I23) -> 2.1339508 | J24: =SUM(J20:J23) -> 0.04241791
C25: Total Water Treatment Process Costs | D25: =SUM(D12,D17,D24) -> 17.57344 | E25: =SUM(E12,E17,E24) -> 7.5825874 | F25: =SUM(F17,F12,F24) -> 0.10653361 | H25: =SUM(H17,H12,H24) -> 18.817604 | I25: =SUM(I17,I12,I24) -> 5.359786 | J25: =SUM(J24+J12+J17) -> 0.10653991
B27: Syrup Preparation Process | C27: Syrup Preparation
C28: Machinery | D28: Total Hourly Cost (€) | E28: Total Depreciation per MT (€/MT) | F28: Percentage of the Total Cost (%) | H28: Total Hourly Cost (€) | I28: Total Depreciation per MT (€/MT) | J28: Percentage of the Total Cost (%)
C29: Jacket Mixing Tank with High Shear Mixer | D29: ='3.2 Syrup Preparation (3)'!F33 -> 0.1171875 | E29: ='3.2 Syrup Preparation (3)'!G33 -> 0.05944577 | F29: =D29/$D$118 -> 0.00071041342 | H29: ='3.2 Syrup Preparation (3)'!F38 -> 1.328125 | I29: ='3.2 Syrup Preparation (3)'!G38 -> 0.46176119 | J29: =H29/$H$118 -> 0.0075194649
C30: Total Machinery Cost | D30: =SUM(D29:D29) -> 0.1171875 | E30: =SUM(E29:E29) -> 0.05944577 | F30: =SUM(F29:F29) -> 0.00071041342 | H30: =SUM(H29:H29) -> 1.328125 | I30: =SUM(I29:I29) -> 0.46176119 | J30: =SUM(J29:J29) -> 0.0075194649
C32: Utility | D32: Total Hourly Cost (€) | E32: Total Cost per MT (€/MT) | F32: Percentage of the Total Cost (%) | H32: Total Hourly Cost (€) | I32: Total Cost per MT (€/MT) | J32: Percentage of the Total Cost (%)
C33: Electricity and Natural Gas Cost | D33: ='3.2 Syrup Preparation (3)'!F44 -> 10.525001 | E33: ='3.2 Syrup Preparation (3)'!G44 -> 5.3390234 | F33: =D33/$D$118 -> 0.063804605 | H33: ='3.2 Syrup Preparation (3)'!F48 -> 11.377274 | I33: ='3.2 Syrup Preparation (3)'!G48 -> 3.9556394 | J33: =H33/$H$118 -> 0.064414881
C34: Other Utility Cost | D34: =15%*D33 -> 1.5787502 | E34: =15%*E33 -> 0.80085351 | F34: =D34/$D$118 -> 0.0095706908 | H34: =15%*H33 -> 1.7065911 | I34: =15%*I33 -> 0.59334591 | J34: =H34/$H$118 -> 0.0096622322
C35: Total Utility Cost | D35: =SUM(D33:D34) -> 12.103751 | E35: =SUM(E33:E34) -> 6.1398769 | F35: =SUM(F33:F34) -> 0.073375296 | H35: =SUM(H33:H34) -> 13.083865 | I35: =SUM(I33:I34) -> 4.5489853 | J35: =SUM(J33:J34) -> 0.074077113
C37: Labour Cost | D37: Total Hourly Cost (€) | E37: Total Cost per MT (€/MT) | F37: Percentage of the Total Cost (%) | H37: Total Hourly Cost (€) | I37: Total Cost per MT (€/MT) | J37: Percentage of the Total Cost (%)
C38: Production Manager | D38: ='3.2 Syrup Preparation (3)'!F53 -> 2.2505195 | E38: ='3.2 Syrup Preparation (3)'!G53 -> 1.1416223 | F38: =D38/$D$118 -> 0.013643087 | H38: ='3.2 Syrup Preparation (3)'!F60 -> 2.2505195 | I38: ='3.2 Syrup Preparation (3)'!G60 -> 0.78245838 | J38: =H38/$H$118 -> 0.012741799
C39: Shift Supervisor | D39: ='3.2 Syrup Preparation (3)'!F54 -> 1.8653017 | E39: ='3.2 Syrup Preparation (3)'!G54 -> 0.94621266 | F39: =D39/$D$118 -> 0.011307822 | H39: ='3.2 Syrup Preparation (3)'!F61 -> 1.8653017 | I39: ='3.2 Syrup Preparation (3)'!G61 -> 0.64852625 | J39: =H39/$H$118 -> 0.010560806
C40: Machine Operator | D40: ='3.2 Syrup Preparation (3)'!F55 -> 1.1616204 | E40: ='3.2 Syrup Preparation (3)'!G55 -> 0.58925586 | F40: =D40/$D$118 -> 0.0070419691 | H40: ='3.2 Syrup Preparation (3)'!F62 -> 2.3232409 | I40: ='3.2 Syrup Preparation (3)'!G62 -> 0.8077421 | J40: =H40/$H$118 -> 0.013153527
C41: Production Worker | D41: ='3.2 Syrup Preparation (3)'!F56 -> 2.214619 | E41: ='3.2 Syrup Preparation (3)'!G56 -> 1.1234111 | F41: =D41/$D$118 -> 0.013425451 | H41: ='3.2 Syrup Preparation (3)'!F63 -> 2.214619 | I41: ='3.2 Syrup Preparation (3)'!G63 -> 0.76997655 | J41: =H41/$H$118 -> 0.012538541
C42: Total labor Cost | D42: =SUM(D38:D41) -> 7.4920606 | E42: =SUM(E38:E41) -> 3.8005019 | F42: =SUM(F38:F41) -> 0.045418329 | H42: =SUM(H38:H41) -> 8.6536811 | I42: =SUM(I38:I41) -> 3.0087033 | J42: =SUM(J38:J41) -> 0.048994674
C43: Total Syrup Preparation Process Costs | D43: =SUM(D30,D35,D42) -> 19.713 | E43: =SUM(E30,E35,E42) -> 9.9998246 | F43: =SUM(F42,F30,F35) -> 0.11950404 | H43: =SUM(H42,H35,H30) -> 23.065671 | I43: =SUM(I42,I35,I30) -> 8.0194498 | J43: =SUM(J30,J35,J42) -> 0.13059125
B45: Mixing Process | C45: Mixing Process
C46: Machinery | D46: Total Hourly Cost (€) | E46: Total Depreciation per MT (€/MT) | F46: Percentage of the Total Cost (%) | H46: Total Hourly Cost (€) | I46: Total Depreciation per MT (€/MT) | J46: Percentage of the Total Cost (%)
C47: Pressure Blending Tank | D47: ='3.4 Mixing (3)'!F33 -> 0.78125 | E47: ='3.4 Mixing (3)'!G33 -> 0.12001063 | F47: =D47/$D$118 -> 0.0047360895 | H47: ='3.4 Mixing (3)'!F38 -> 0.91796875 | I47: ='3.4 Mixing (3)'!G38 -> 0.049434317 | J47: =H47/$H$118 -> 0.0051972772
C48: Total Machinery Cost | D48: =SUM(D47) -> 0.78125 | E48: =SUM(E47) -> 0.12001063 | F48: =SUM(F47:F47) -> 0.0047360895 | H48: =SUM(H47:H47) -> 0.91796875 | I48: =SUM(I47:I47) -> 0.049434317 | J48: =SUM(J47:J47) -> 0.0051972772
C50: Utility | D50: Total Hourly Cost (€) | E50: Total Cost per MT (€/MT) | F50: Percentage of the Total Cost (%) | H50: Total Hourly Cost (€) | I50: Total Cost per MT (€/MT) | J50: Percentage of the Total Cost (%)
C51: Electricity and Natural Gas Cost | D51: ='3.4 Mixing (3)'!F44 -> 3.7068185 | E51: ='3.4 Mixing (3)'!G44 -> 0.56941775 | F51: =D51/$D$118 -> 0.022471455 | H51: ='3.4 Mixing (3)'!F48 -> 4.5590914 | I51: ='3.4 Mixing (3)'!G48 -> 0.24551551 | J51: =H51/$H$118 -> 0.025812275
C52: Other Utility Cost | D52: =15%*D51 -> 0.55602278 | E52: =15%*E51 -> 0.085412662 | F52: =D52/$D$118 -> 0.0033707183 | H52: =15%*H51 -> 0.68386371 | I52: =15%*I51 -> 0.036827327 | J52: =H52/$H$118 -> 0.0038718413
C53: Total Utility Cost | D53: =SUM(D51:D52) -> 4.2628413 | E53: =SUM(E51:E52) -> 0.65483041 | F53: =SUM(F51:F52) -> 0.025842173 | H53: =SUM(H51:H52) -> 5.2429551 | I53: =SUM(I51:I52) -> 0.28234284 | J53: =SUM(J51:J52) -> 0.029684116
...

Sheet 2.2 Cost Model Packing
C5: Summary – Packing Cost
D7: Semi-Automatic | H7: Automatic
C8: Dry Aseptic Cleaning Process
B9: Dry Aseptic Cleaning Process | C9: Machinery | D9: Total Hourly Cost (€) | E9: Total Depreciation per MT (€/MT) | F9: Percentage of the Total Cost (%) | H9: Total Hourly Cost (€) | I9: Total Depreciation per MT (€/MT) | J9: Percentage of the Total Cost (%)
C10: Preform Steriliser | D10: ='4.1 Dry Aseptic Cleaning'!F34 -> 0.37760417 | E10: =IF('1.1 Summary'!C15="Can",0,'4.1 Dry Aseptic Cleaning'!G34) -> 0.020070516 | F10: =D10/$D$235 -> 0.0015992035 | H10: ='4.1 Dry Aseptic Cleaning'!F39 -> 0.45572917 | I10: =IF('1.1 Summary'!$C$15="Can",0,'4.1 Dry Aseptic Cleaning'!G39) -> 0.019957999 | J10: =H10/H$235 -> 0.0018575227
C11: Air Jet and Vacuum Cleaning Machines | D11: ='4.1 Dry Aseptic Cleaning'!F35 -> 0.25390625 | E11: =IF('1.1 Summary'!C15="Can",0,'4.1 Dry Aseptic Cleaning'!G35) -> 0.013495692 | F11: =D11/$D$235 -> 0.0010753265 | H11: ='4.1 Dry Aseptic Cleaning'!F40 -> 0.3125 | I11: =IF('1.1 Summary'!$C$15="Can",0,'4.1 Dry Aseptic Cleaning'!G40) -> 0.013685485 | J11: =H11/H$235 -> 0.0012737299
C12: Total Machinery Cost | D12: =SUM(D10:D11) -> 0.63151042 | E12: =SUM(E10:E11) -> 0.033566208 | F12: =SUM(F10:F11) -> 0.0026745299 | H12: =SUM(H10:H11) -> 0.76822917 | I12: =SUM(I10:I11) -> 0.033643485 | J12: =SUM(J10:J11) -> 0.0031312526
C14: Utility | D14: Total Hourly Cost (€) | E14: Total Cost per MT (€/MT) | F14: Percentage of the Total Cost (%) | H14: Total Hourly Cost (€) | I14: Total Cost per MT (€/MT) | J14: Total Cost per MT (€/MT)
C15: Electricity and Natural Gas Cost | D15: ='4.1 Dry Aseptic Cleaning'!F47 -> 4.3065661 | E15: =IF('1.1 Summary'!C15="Can",0,'4.1 Dry Aseptic Cleaning'!G47) -> 0.22890373 | F15: =D15/$D$235 -> 0.018238876 | H15: ='4.1 Dry Aseptic Cleaning'!F52 -> 4.9378793 | I15: =IF('1.1 Summary'!C15="Can",0,'4.1 Dry Aseptic Cleaning'!G52) -> 0.21624728 | J15: =H15/$H$235 -> 0.020126478
C16: Other Utility Cost | D16: =15%*D15 -> 0.64598491 | E16: =15%*E15 -> 0.03433556 | F16: =D16/$D$235 -> 0.0027358313 | H16: =15%*H15 -> 0.7406819 | I16: =15%*I15 -> 0.032437092 | J16: =H16/$H$235 -> 0.0030189717
C17: Total Utility Cost | D17: =SUM(D15:D16) -> 4.952551 | E17: =SUM(E15:E16) -> 0.2632393 | F17: =SUM(F15:F16) -> 0.020974707 | H17: =SUM(H15:H16) -> 5.6785612 | I17: =SUM(I15:I16) -> 0.24868437 | J17: =SUM(J15:J16) -> 0.02314545
C20: Labour Cost | D20: Total Hourly Cost (€) | E20: Total Cost per MT (€/MT) | F20: Percentage of the Total Cost (%) | H20: Total Hourly Cost (€) | I20: Total Cost per MT (€/MT) | J20: Percentage of the Total Cost (%)
C21: Production Manager | D21: ='4.1 Dry Aseptic Cleaning'!F58 -> 2.2505195 | E21: =IF('1.1 Summary'!$C$15="Can",0,'4.1 Dry Aseptic Cleaning'!G58) -> 0.1196202 | F21: =D21/$D$235 -> 0.0095312468 | H21: ='4.1 Dry Aseptic Cleaning'!F65 -> 2.2505195 | I21: =IF('1.1 Summary'!$C$15="Can",0,'4.1 Dry Aseptic Cleaning'!G65) -> 0.098558243 | J21: =H21/$H$235 -> 0.0091729723
C22: Shift Supervisor | D22: ='4.1 Dry Aseptic Cleaning'!F59 -> 1.8653017 | E22: =IF('1.1 Summary'!$C$15="Can",0,'4.1 Dry Aseptic Cleaning'!G59) -> 0.099145007 | F22: =D22/$D$235 -> 0.0078997988 | H22: ='4.1 Dry Aseptic Cleaning'!F66 -> 1.8653017 | I22: =IF('1.1 Summary'!$C$15="Can",0,'4.1 Dry Aseptic Cleaning'!G66) -> 0.081688189 | J22: =H22/$H$235 -> 0.0076028495
C23: Machine Operator | D23: ='4.1 Dry Aseptic Cleaning'!F60 -> 1.1616204 | E23: =IF('1.1 Summary'!$C$15="Can",0,'4.1 Dry Aseptic Cleaning'!G60) -> 0.061742756 | F23: =D23/$D$235 -> 0.0049196158 | H23: ='4.1 Dry Aseptic Cleaning'!F67 -> 1.1616204 | I23: =IF('1.1 Summary'!$C$15="Can",0,'4.1 Dry Aseptic Cleaning'!G67) -> 0.050871486 | J23: =H23/$H$235 -> 0.0047346901
C24: Production Worker | D24: ='4.1 Dry Aseptic Cleaning'!F61 -> 2.214619 | E24: =IF('1.1 Summary'!$C$15="Can",0,'4.1 Dry Aseptic Cleaning'!G61) -> 0.11771201 | F24: =D24/$D$235 -> 0.0093792037 | H24: ='4.1 Dry Aseptic Cleaning'!F68 -> 2.214619 | I24: =IF('1.1 Summary'!$C$15="Can",0,'4.1 Dry Aseptic Cleaning'!G68) -> 0.096986035 | J24: =H24/$H$235 -> 0.0090266444
C25: Total labor Cost | D25: =SUM(D21:D24) -> 7.4920606 | E25: =SUM(E21:E24) -> 0.39821998 | F25: =SUM(F21:F24) -> 0.031729865 | H25: =SUM(H21:H24) -> 7.4920606 | I25: =SUM(I21:I24) -> 0.32810395 | J25: =SUM(J21:J24) -> 0.030537156
C26: Total Dry Aseptic Cleaning Cost | D26: =D25+D17+D12 -> 13.076122 | E26: =E25+E17+E12 -> 0.69502548 | F26: =SUM(F25,F17,F12) -> 0.055379102 | H26: =H25+H17+H12 -> 13.938851 | I26: =I25+I17+I12 -> 0.61043181 | J26: =SUM(J25,J17,J12) -> 0.056813858
D28: Semi-Automatic | H28: Automatic
C29: PET Bottle Blowing Process
B30: PET Bottle Blowing Process | C30: Machinery | D30: Total Hourly Cost (€) | E30: Total Depreciation per MT (€/MT) | F30: Percentage of the Total Cost (%) | H30: Total Hourly Cost (€) | I30: Total Depreciation per MT (€/MT) | J30: Percentage of the Total Cost (%)
C31: PET Bottle Blowing Machine | D31: =IF('1.1 Summary'!$C$15="Can",0,'4.2 PET Bottle Blowing'!F34) -> 0.67708333 | E31: =IF('1.1 Summary'!$C$15="Can",0,'4.2 PET Bottle Blowing'!G34) -> 0.050004026 | F31: =D31/$D$235 -> 0.0028675372 | H31: =IF('1.1 Summary'!$C$15="Can",0,'4.2 PET Bottle Blowing'!F38) -> 0.71614583 | I31: =IF('1.1 Summary'!$C$15="Can",0,'4.2 PET Bottle Blowing'!G38) -> 0.042221739 | J31: =H31/H$235 -> 0.0029189643
C32: Total Machinery Cost | D32: =SUM(D31:D31) -> 0.67708333 | E32: =SUM(E31:E31) -> 0.050004026 | F32: =SUM(F31:F31) -> 0.0028675372 | H32: =SUM(H31:H31) -> 0.71614583 | I32: =SUM(I31:I31) -> 0.042221739 | J32: =SUM(J31:J31) -> 0.0029189643
C34: Utility | D34: Total Hourly Cost (€) | E34: Total Cost per MT (€/MT) | F34: Percentage of the Total Cost (%) | H34: Total Hourly Cost (€) | I34: Total Cost per MT (€/MT) | J34: Total Cost per MT (€/MT)
C35: Electricity and Natural Gas Cost | D35: =IF('1.1 Summary'!$C$15="Can",0,'4.2 PET Bottle Blowing'!F45) -> 12.197981 | E35: =IF('1.1 Summary'!$C$15="Can",0,'4.2 PET Bottle Blowing'!G45) -> 0.90084653 | F35: =D35/$D$235 -> 0.05166006 | H35: =IF('1.1 Summary'!$C$15="Can",0,'4.2 PET Bottle Blowing'!F49) -> 12.671466 | I35: =IF('1.1 Summary'!$C$15="Can",0,'4.2 PET Bottle Blowing'!G49) -> 0.74707038 | J35: =H35/$H$235 -> 0.05164808
C36: Other Utility Cost | D36: =15%*D35 -> 1.8296972 | E36: =15%*E35 -> 0.13512698 | F36: =D36/$D$235 -> 0.007749009 | H36: =15%*H35 -> 1.9007199 | I36: =15%*I35 -> 0.11206056 | J36: =H36/$H$235 -> 0.007747212
C37: Total Utility Cost | D37: =SUM(D35:D36) -> 14.027679 | E37: =SUM(E35:E36) -> 1.0359735 | F37: =SUM(F35:F36) -> 0.059409069 | H37: =SUM(H35:H36) -> 14.572186 | I37: =SUM(I35:I36) -> 0.85913094 | J37: =SUM(J35:J36) -> 0.059395292
C40: Labour Cost | D40: Total Hourly Cost (€) | E40: Total Cost per MT (€/MT) | F40: Percentage of the Total Cost (%) | H40: Total Hourly Cost (€) | I40: Total Cost per MT (€/MT) | J40: Percentage of the Total Cost (%)
C41: Production Manager | D41: =IF('1.1 Summary'!$C$15="Can",0,'4.2 PET Bottle Blowing'!F54) -> 2.2505195 | E41: =IF('1.1 Summary'!$C$15="Can",0,'4.2 PET Bottle Blowing'!G54) -> 0.16620559 | F41: =D41/$D$235 -> 0.0095312468 | H41: =IF('1.1 Summary'!$C$15="Can",0,'4.2 PET Bottle Blowing'!F61) -> 2.2505195 | I41: =IF('1.1 Summary'!$C$15="Can",0,'4.2 PET Bottle Blowing'!G61) -> 0.13268365 | J41: =H41/$H$235 -> 0.0091729723
